<?xml version="1.0" encoding="UTF-8"?>
<!-- Generated by org.testng.reporters.JUnitReportReporter -->
<testsuite hostname="DESKTOP-VNAON2C" failures="1" tests="6" name="com.qa.adminTest.CategoriesTest" time="60.210" errors="0" timestamp="2024-01-03T15:57:31 IST" skipped="0">
  <testcase classname="com.qa.adminTest.CategoriesTest" name="createNewCategory" time="19.019">
    <failure message="expected [true] but found [false]" type="java.lang.AssertionError">
      <![CDATA[java.lang.AssertionError: expected [true] but found [false]
at org.testng.Assert.fail(Assert.java:110)
at org.testng.Assert.failNotEquals(Assert.java:1577)
at org.testng.Assert.assertTrue(Assert.java:56)
at org.testng.Assert.assertTrue(Assert.java:66)
at com.qa.adminTest.CategoriesTest.createNewCategory(CategoriesTest.java:48)
at java.base/jdk.internal.reflect.NativeMethodAccessorImpl.invoke0(Native Method)
at java.base/jdk.internal.reflect.NativeMethodAccessorImpl.invoke(NativeMethodAccessorImpl.java:77)
at java.base/jdk.internal.reflect.DelegatingMethodAccessorImpl.invoke(DelegatingMethodAccessorImpl.java:43)
at java.base/java.lang.reflect.Method.invoke(Method.java:568)
at org.testng.internal.invokers.MethodInvocationHelper.invokeMethod(MethodInvocationHelper.java:139)
at org.testng.internal.invokers.TestInvoker.invokeMethod(TestInvoker.java:677)
at org.testng.internal.invokers.TestInvoker.invokeTestMethod(TestInvoker.java:221)
at org.testng.internal.invokers.MethodRunner.runInSequence(MethodRunner.java:50)
at org.testng.internal.invokers.TestInvoker$MethodInvocationAgent.invoke(TestInvoker.java:969)
at org.testng.internal.invokers.TestInvoker.invokeTestMethods(TestInvoker.java:194)
at org.testng.internal.invokers.TestMethodWorker.invokeTestMethods(TestMethodWorker.java:148)
at org.testng.internal.invokers.TestMethodWorker.run(TestMethodWorker.java:128)
at java.base/java.util.ArrayList.forEach(ArrayList.java:1511)
at org.testng.TestRunner.privateRun(TestRunner.java:829)
at org.testng.TestRunner.run(TestRunner.java:602)
at org.testng.SuiteRunner.runTest(SuiteRunner.java:437)
at org.testng.SuiteRunner$SuiteWorker.run(SuiteRunner.java:475)
at org.testng.internal.thread.ThreadUtil.lambda$execute$0(ThreadUtil.java:58)
at java.base/java.util.concurrent.FutureTask.run(FutureTask.java:264)
at java.base/java.util.concurrent.ThreadPoolExecutor.runWorker(ThreadPoolExecutor.java:1136)
at java.base/java.util.concurrent.ThreadPoolExecutor$Worker.run(ThreadPoolExecutor.java:635)
at java.base/java.lang.Thread.run(Thread.java:840)
]]>
    </failure>
  </testcase> <!-- createNewCategory -->
  <system-out/>
  <testcase classname="com.qa.adminTest.CategoriesTest" name="updateCategory" time="15.293"/>
  <system-out/>
  <testcase classname="com.qa.adminTest.CategoriesTest" name="deleteCategory" time="7.333"/>
  <system-out/>
  <testcase classname="com.qa.adminTest.CategoriesTest" name="addSubcategoryInCategory" time="6.514"/>
  <system-out/>
  <testcase classname="com.qa.adminTest.CategoriesTest" name="updateSubcategory" time="5.404"/>
  <system-out/>
  <testcase classname="com.qa.adminTest.CategoriesTest" name="deleteSubcategory" time="6.647"/>
  <system-out/>
</testsuite> <!-- com.qa.adminTest.CategoriesTest -->
